Workbook

Sheet Instrucciones
A1: Checklist de Pruebas y Validación Técnica — Proyecto Vending WPOSS
A3: Cómo usar este libro
A4: Este libro traduce el documento de contexto del checklist en una plantilla de trabajo. Cada pestaña cubre un bloque del checklist y se enlazan entre sí mediante el campo 'Sesión ID' (identificador único de cada visita/sesión de pruebas, ej. SES-001).
A6: Pestañas
A7: 1. Identificación y Versiones — una fila por sesión: equipo, responsables, firmware, versión MDB, Financiera y Agente Polaris.
A8: 2. Revisión Física y Eléctrica — checklist de inspección física por sesión (duplicar el bloque de ítems para cada Sesión ID nueva).
A9: 3. Casos de Prueba — tabla detallada de casos ejecutados o revisados documentalmente, por componente (POS, MDB, Financiera, Agente Polaris, Operación/Dispensación).
A10: 4. Incidencias — registro de hallazgos/incidencias con trazabilidad a la prueba y sesión que las originó.
A11: 5. Cierre de Sesión — resumen de cierre por sesión: trae automáticamente los datos del equipo y de la visita desde 'Identificación y Versiones', calcula los totales desde 'Casos de Prueba' e 'Incidencias', y arma en la columna 'Resumen para correo' un bloque de texto listo para copiar y pegar en un correo. Las columnas C:R (datos de equipo) están agrupadas/colapsadas — use el '+' sobre la columna R para expandirlas si necesita verlas o editar el cálculo.
A13: Leyenda de colores
A14: Fila amarilla (EJEMPLO) = fila ilustrativa de formato esperado. Bórrela o reemplácela antes de registrar datos reales.
A15: Celda verde claro = campo calculado automáticamente por fórmula; no escribir directamente sobre ella.
... A38: • ¿Cuáles son los criterios de salida para considerar una combinación apta para piloto?

Sheet Listas
A1: Estados | B1: Severidad | C1: Tipo de verificación | D1: Componente | E1: Tipo de prueba (sesión) | F1: Estado de incidencia | G1: Concepto final
A2: Aprobado | B2: Crítica | C2: Prueba ejecutada | D2: Máquina Vending | E2: Instalación | F2: Abierto | G2: Apto para piloto
A3: Fallido | B3: Alta | C3: Revisión documental | D3: POS NEW5320 | E3: Diagnóstico | F3: En progreso | G3: Apto con condiciones
A4: Bloqueado | B4: Media | D4: MDB | E4: Compatibilidad | F4: Pendiente de reprueba | G4: No apto
A5: Pendiente | B5: Baja | D5: Financiera | E5: Piloto | F5: Cerrado | G5: Pendiente
A6: No aplica | D6: Agente Polaris | E6: Actualización de versión
A7: En observación | D7: Operación / Dispensación | E7: Regresión
D8: Otro | E8: Otro

Sheet Identificación y Versiones
A1: Sesión ID | B1: Fecha | C1: Hora | D1: Responsable | E1: Participantes | F1: Cliente / Piloto | G1: Fabricante máquina | H1: Modelo máquina | I1: Serial máquina | J1: Modelo POS | K1: Serial POS | L1: Objetivo de la sesión | M1: Tipo de prueba | N1: Firmware NEW5320 | O1: MDB — Estándar / Especificación | P1: MDB — Versión de implementación | Q1: MDB — Módulo de software | R1: Versión Financiera | S1: Versión Agente Polaris | T1: Configuraciones relevantes | U1: Versión anterior (si aplica) | V1: Versión nueva (si aplica) | W1: Fecha de instalación | X1: Identificador de compilación / checksum | Y1: Compatibilidad prevista | Z1: Observaciones
A2: SES-001 | B2: 2026-10-26 | C2: 10:30 | D2: Pendiente de confirmar | E2: Pendiente de confirmar | F2: Pendiente de confirmar | G2: Pendiente de confirmar | H2: Pendiente de confirmar | I2: Pendiente de confirmar | J2: NEW5320 | K2: Pendiente de confirmar | L2: Validación inicial de comunicación MDB | M2: Diagnóstico | N2: Pendiente de confirmar | O2: Pendiente de confirmar | P2: Pendiente de confirmar | Q2: Pendiente de confirmar | R2: Pendiente de confirmar | S2: Pendiente de confirmar | T2: Pendiente de confirmar | U2: N/A | V2: N/A | W2: N/A | X2: N/A | Y2: Pendiente de confirmar | Z2: Fila de ejemplo — reemplazar con datos reales de la sesión
A3: SES-002 | B3: 2026-10-26 | C3: 10:30 | D3: Técnico A | E3: Equipo técnico WPOSS / Equipo técnico del cliente | F3: Cliente Ficticio Uno | G3: Fabricante A | H3: Modelo A-1 | I3: SERIAL-MAQ-0001 | J3: NEW5320 | K3: SERIAL-POS-0001 | L3: Validación inicial de comunicación MDB | M3: Compatibilidad | N3: 13.0.13 | O3: Estándar | P3: Estándar | Q3: Estándar | R3: Estándar | S3: Estándar | T3: Estándar | U3: N/A | V3: N/A | W3: N/A | X3: N/A | Y3: Compatible | Z3: sin gestion dex
A4: SES-003 | B4: 2026-10-26 | C4: 0.58333333 | D4: Técnico B | E4: Equipo técnico WPOSS / Técnico C | F4: Cliente Ficticio Dos | G4: Fabricante B | J4: NEW5320 | K4: SERIAL-POS-0002 | L4: Validación inicial de comunicación MDB | M4: Diagnóstico | N4: 13.0.22 | O4: Estándar | P4: Estándar | Q4: Estándar | R4: MDB_FINANCIAL_TEST_1.0.0_260622 | S4: DRIVER_MDB_1.0.0_261020-TEST | T4: Estándar | U4: N/A | V4: N/A | W4: N/A | X4: N/A | Y4: Compatible | Z4: sin gestion dex

Sheet Revisión Física y Eléctrica
A1: Sesión ID | B1: Ítem de revisión | C1: Resultado | D1: Evidencia | E1: Observaciones
A2: SES-001 | B2: Estado físico de la máquina vending | C2: Pendiente | E2: Fila de ejemplo — duplicar este bloque de ítems por cada Sesión ID
A3: SES-001 | B3: Estado físico del POS NEW5320 | C3: Pendiente | E3: Fila de ejemplo — duplicar este bloque de ítems por cada Sesión ID
A4: SES-001 | B4: Cables y conectores (estado e integridad) | C4: Pendiente | E4: Fila de ejemplo — duplicar este bloque de ítems por cada Sesión ID
A5: SES-001 | B5: Interfaces disponibles en la máquina (puertos identificados) | C5: Pendiente | E5: Fila de ejemplo — duplicar este bloque de ítems por cada Sesión ID
A6: SES-001 | B6: Adaptadores utilizados (tipo y compatibilidad) | C6: Pendiente | E6: Fila de ejemplo — duplicar este bloque de ítems por cada Sesión ID
A7: SES-001 | B7: Alimentación utilizada y especificaciones (voltaje/corriente medidos si aplica) | C7: Pendiente | E7: Fila de ejemplo — duplicar este bloque de ítems por cada Sesión ID
A8: SES-001 | B8: Fotografías de conexiones tomadas | C8: Pendiente | E8: Fila de ejemplo — duplicar este bloque de ítems por cada Sesión ID
A9: SES-001 | B9: Condiciones de seguridad y preparación verificadas | C9: Pendiente | E9: Fila de ejemplo — duplicar este bloque de ítems por cada Sesión ID
A10: SES-002 | B10: Estado físico de la máquina vending | C10: Aprobado | E10: Fila de ejemplo — duplicar este bloque de ítems por cada Sesión ID
A11: SES-002 | B11: Estado físico del POS NEW5320 | C11: Aprobado | E11: Fila de ejemplo — duplicar este bloque de ítems por cada Sesión ID
A12: SES-002 | B12: Cables y conectores (estado e integridad) | C12: Aprobado | E12: Fila de ejemplo — duplicar este bloque de ítems por cada Sesión ID
A13: SES-002 | B13: Interfaces disponibles en la máquina (puertos identificados) | C13: No aplica | E13: Fila de ejemplo — duplicar este bloque de ítems por cada Sesión ID
... A25: SES-003 | B25: Condiciones de seguridad y preparación verificadas | C25: Fallido | E25: no se cuenta con energia

Sheet Casos de Prueba
A1: ID de prueba | B1: Sesión ID | C1: Componente | D1: Tipo de verificación | E1: Objetivo | F1: Precondiciones | G1: Procedimiento | H1: Resultado esperado | I1: Resultado obtenido | J1: Estado | K1: Evidencia | L1: Observaciones | M1: Responsable | N1: Incidencia asociada | O1: Siguiente acción
A2: POS-001 | B2: SES-001 | C2: POS NEW5320 | D2: Prueba ejecutada | E2: Verificar encendido y energización correcta del POS | F2: POS conectado al puerto MDB correspondiente, máquina apagada antes de conectar | G2: 1) Apagar máquina. 2) Conectar cable al puerto identificado como MDB. 3) Encender máquina. 4) Observar encendido del POS. | H2: El POS enciende y el lector de tarjetas queda activo | I2: Pendiente de confirmar | J2: Pendiente | L2: Fila de ejemplo — reemplazar con datos reales | M2: Pendiente de confirmar | O2: Pendiente de confirmar
A3: MDB-001 | B3: SES-001 | C3: MDB | D3: Prueba ejecutada | E3: Verificar dirección Cashless configurada en el bus MDB | F3: POS energizado y comunicando en el bus MDB | G3: 1) Conectar sniffer/herramienta de diagnóstico. 2) Capturar tráfico. 3) Identificar dirección reportada por el dispositivo. | H3: La dirección coincide con la documentada por el fabricante (no asumir 0x10 de fábrica) | I3: Pendiente de confirmar | J3: Pendiente | L3: Fila de ejemplo — reemplazar con datos reales | M3: Pendiente de confirmar | O3: Pendiente de confirmar
A4: FIN-001 | B4: SES-001 | C4: Financiera | D4: Prueba ejecutada | E4: Verificar transacción autorizada de punta a punta | F4: Componente Financiera inicializado y conectividad confirmada | G4: 1) Iniciar operación. 2) Autorizar pago de prueba. 3) Verificar código de respuesta. | H4: Transacción aprobada con código de respuesta esperado, sin afectar datos sensibles en evidencia | I4: Pendiente de confirmar | J4: Pendiente | L4: Fila de ejemplo — reemplazar con datos reales | M4: Pendiente de confirmar | O4: Pendiente de confirmar
A5: AGP-001 | B5: SES-001 | C5: Agente Polaris | D5: Revisión documental | E5: Confirmar versión instalada del Agente Polaris | F5: Acceso al dispositivo donde se ejecuta el agente (pendiente de confirmar cuál) | G5: 1) Consultar versión instalada. 2) Documentar. | H5: Versión documentada coincide con la versión esperada para la sesión | I5: Pendiente de confirmar | J5: Pendiente | L5: Fila de ejemplo — reemplazar con datos reales | M5: Pendiente de confirmar | O5: Pendiente de confirmar
A6: VEN-001 | B6: SES-001 | C6: Operación / Dispensación | D6: Prueba ejecutada | E6: Verificar consistencia entre aprobación financiera y dispensación física | F6: Producto seleccionado con precio definido, pago aprobado en caso FIN-001 | G6: 1) Seleccionar producto. 2) Pagar. 3) Verificar dispensación física del producto. | H6: El producto se dispensa únicamente cuando el pago fue aprobado; no hay duplicidad | I6: Pendiente de confirmar | J6: Pendiente | L6: Fila de ejemplo — reemplazar con datos reales | M6: Pendiente de confirmar | O6: Pendiente de confirmar
A7: POS-002 | B7: SES-002 | C7: POS NEW5320 | D7: Prueba ejecutada | E7: Verificar encendido y energización correcta del POS | F7: POS conectado al puerto MDB correspondiente, máquina apagada antes de conectar | G7: 1) Apagar máquina. 2) Conectar cable al puerto identificado como MDB. 3) Encender máquina. 4) Observar encendido del POS. | H7: El POS enciende y el lector de tarjetas queda activo | I7: Pendiente de confirmar | J7: Aprobado | L7: Fila de ejemplo — reemplazar con datos reales | M7: Pendiente de confirmar | O7: Pendiente de confirmar
A8: MDB-002 | B8: SES-002 | C8: MDB | D8: Prueba ejecutada | E8: Verificar dirección Cashless configurada en el bus MDB | F8: POS energizado y comunicando en el bus MDB | G8: 1) Conectar sniffer/herramienta de diagnóstico. 2) Capturar tráfico. 3) Identificar dirección reportada por el dispositivo. | H8: La dirección coincide con la documentada por el fabricante (no asumir 0x10 de fábrica) | I8: Pendiente de confirmar | J8: Aprobado | L8: Fila de ejemplo — reemplazar con datos reales | M8: Pendiente de confirmar | O8: Pendiente de confirmar
A9: FIN-002 | B9: SES-002 | C9: Financiera | D9: Prueba ejecutada | E9: Verificar transacción autorizada de punta a punta | F9: Componente Financiera inicializado y conectividad confirmada | G9: 1) Iniciar operación. 2) Autorizar pago de prueba. 3) Verificar código de respuesta. | H9: Transacción aprobada con código de respuesta esperado, sin afectar datos sensibles en evidencia | I9: Pendiente de confirmar | J9: Fallido | L9: mdb_gateway_anonimizado | M9: Pendiente de confirmar | O9: Pendiente de confirmar
A10: AGP-002 | B10: SES-002 | C10: Agente Polaris | D10: Revisión documental | E10: Confirmar versión instalada del Agente Polaris | F10: Acceso al dispositivo donde se ejecuta el agente (pendiente de confirmar cuál) | G10: 1) Consultar versión instalada. 2) Documentar. | H10: Versión documentada coincide con la versión esperada para la sesión | I10: Pendiente de confirmar | J10: No aplica | L10: Fila de ejemplo — reemplazar con datos reales | M10: Pendiente de confirmar | O10: Pendiente de confirmar
A11: VEN-002 | B11: SES-002 | C11: Operación / Dispensación | D11: Prueba ejecutada | E11: Verificar consistencia entre aprobación financiera y dispensación física | F11: Producto seleccionado con precio definido, pago aprobado en caso FIN-001 | G11: 1) Seleccionar producto. 2) Pagar. 3) Verificar dispensación física del producto. | H11: El producto se dispensa únicamente cuando el pago fue aprobado; no hay duplicidad | I11: Pendiente de confirmar | J11: Pendiente | L11: No se cuenta con energia | M11: Pendiente de confirmar | O11: Pendiente de confirmar
A12: POS-003 | B12: SES-003 | C12: POS NEW5320 | D12: Prueba ejecutada | E12: Verificar encendido y energización correcta del POS | F12: POS conectado al puerto MDB correspondiente, máquina apagada antes de conectar | G12: 1) Apagar máquina. 2) Conectar cable al puerto identificado como MDB. 3) Encender máquina. 4) Observar encendido del POS. | H12: El POS enciende y el lector de tarjetas queda activo | I12: Pendiente de confirmar | J12: Pendiente | L12: No se cuenta con energia | M12: Pendiente de confirmar | O12: Pendiente de confirmar
A13: MDB-003 | B13: SES-003 | C13: MDB | D13: Prueba ejecutada | E13: Verificar dirección Cashless configurada en el bus MDB | F13: POS energizado y comunicando en el bus MDB | G13: 1) Conectar sniffer/herramienta de diagnóstico. 2) Capturar tráfico. 3) Identificar dirección reportada por el dispositivo. | H13: La dirección coincide con la documentada por el fabricante (no asumir 0x10 de fábrica) | I13: Pendiente de confirmar | J13: Pendiente | L13: No se cuenta con energia | M13: Pendiente de confirmar | O13: Pendiente de confirmar
... A16: VEN-003 | B16: SES-003 | C16: Operación / Dispensación | D16: Prueba ejecutada | E16: Verificar consistencia entre aprobación financiera y dispensación física | F16: Producto seleccionado con precio definido, pago aprobado en caso FIN-001 | G16: 1) Seleccionar producto. 2) Pagar. 3) Verificar dispensación física del producto. | H16: El producto se dispensa únicamente cuando el pago fue aprobado; no hay duplicidad | I16: Pendiente de confirmar | J16: Pendiente | L16: No se cuenta con energia | M16: Pendiente de confirmar | O16: Pendiente de confirmar

Sheet Incidencias
A1: ID | B1: Fecha | C1: Sesión ID | D1: Componente y versión | E1: Descripción | F1: Pasos para reproducir | G1: Resultado esperado | H1: Resultado obtenido | I1: Severidad / Prioridad | J1: Evidencia | K1: Responsable | L1: Ticket | M1: Siguiente acción | N1: Estado | O1: Resultado de la reprueba
A2: INC-001 | B2: 2026-10-26 | C2: SES-001 | D2: Pendiente de confirmar | E2: Fila de ejemplo — reemplazar con la descripción real del hallazgo | F2: Pendiente de confirmar | G2: Pendiente de confirmar | H2: Pendiente de confirmar | I2: Media | K2: Pendiente de confirmar | M2: Pendiente de confirmar | N2: Abierto
A3: INC-002 | B3: 2026-10-26 | C3: SES-002 | D3: Pendiente de confirmar | E3: Fila de ejemplo — reemplazar con la descripción real del hallazgo | F3: Pendiente de confirmar | G3: Pendiente de confirmar | H3: Pendiente de confirmar | I3: Media | K3: Pendiente de confirmar | M3: Pendiente de confirmar | N3: Abierto
A4: INC-003 | B4: 2026-10-26 | C4: SES-003 | D4: Pendiente de confirmar | E4: Fila de ejemplo — reemplazar con la descripción real del hallazgo | F4: Pendiente de confirmar | G4: Pendiente de confirmar | H4: Pendiente de confirmar | I4: Media | K4: Pendiente de confirmar | M4: Pendiente de confirmar | N4: Abierto

Sheet Cierre de Sesión
A1: Sesión ID | B1: Fecha de cierre | C1: Fecha de la visita | D1: Cliente / Comercio | E1: Fabricante máquina | F1: Modelo máquina | G1: Serial máquina | H1: Modelo POS | I1: Serial POS | J1: Firmware NEW5320 | K1: MDB — Estándar | L1: MDB — Versión | M1: MDB — Módulo | N1: Versión Financiera | O1: Versión Agente Polaris | P1: Participantes | Q1: Responsable de la sesión | R1: Objetivo de la sesión | S1: Total planificadas | T1: Total ejecutadas | U1: Aprobadas | V1: Fallidas | W1: Bloqueadas | X1: Pendientes | Y1: Incidencias abiertas | Z1: Versiones y equipos cubiertos | AA1: Pendientes (Fabricante/Desarrollo/QA/Cliente) | AB1: Concepto final | AC1: Responsable del cierre | AD1: Resumen para correo
A2: SES-001 | C2: =IF(A2="","",IFERROR(INDEX('Identificación y Versiones'!$B:$B,MATCH(A2,'Identificación y Versiones'!$A:$A,0)),"")) | D2: =IF(A2="","",IFERROR(INDEX('Identificación y Versiones'!$F:$F,MATCH(A2,'Identificación y Versiones'!$A:$A,0)),"")) | E2: =IF(A2="","",IFERROR(INDEX('Identificación y Versiones'!$G:$G,MATCH(A2,'Identificación y Versiones'!$A:$A,0)),"")) | F2: =IF(A2="","",IFERROR(INDEX('Identificación y Versiones'!$H:$H,MATCH(A2,'Identificación y Versiones'!$A:$A,0)),"")) | G2: =IF(A2="","",IFERROR(INDEX('Identificación y Versiones'!$I:$I,MATCH(A2,'Identificación y Versiones'!$A:$A,0)),"")) | H2: =IF(A2="","",IFERROR(INDEX('Identificación y Versiones'!$J:$J,MATCH(A2,'Identificación y Versiones'!$A:$A,0)),"")) | I2: =IF(A2="","",IFERROR(INDEX('Identificación y Versiones'!$K:$K,MATCH(A2,'Identificación y Versiones'!$A:$A,0)),"")) | J2: =IF(A2="","",IFERROR(INDEX('Identificación y Versiones'!$N:$N,MATCH(A2,'Identificación y Versiones'!$A:$A,0)),"")) | K2: =IF(A2="","",IFERROR(INDEX('Identificación y Versiones'!$O:$O,MATCH(A2,'Identificación y Versiones'!$A:$A,0)),"")) | L2: =IF(A2="","",IFERROR(INDEX('Identificación y Versiones'!$P:$P,MATCH(A2,'Identificación y Versiones'!$A:$A,0)),"")) | M2: =IF(A2="","",IFERROR(INDEX('Identificación y Versiones'!$Q:$Q,MATCH(A2,'Identificación y Versiones'!$A:$A,0)),"")) | N2: =IF(A2="","",IFERROR(INDEX('Identificación y Versiones'!$R:$R,MATCH(A2,'Identificación y Versiones'!$A:$A,0)),"")) | O2: =IF(A2="","",IFERROR(INDEX('Identificación y Versiones'!$S:$S,MATCH(A2,'Identificación y Versiones'!$A:$A,0)),"")) | P2: =IF(A2="","",IFERROR(INDEX('Identificación y Versiones'!$E:$E,MATCH(A2,'Identificación y Versiones'!$A:$A,0)),"")) | Q2: =IF(A2="","",IFERROR(INDEX('Identificación y Versiones'!$D:$D,MATCH(A2,'Identificación y Versiones'!$A:$A,0)),"")) | R2: =IF(A2="","",IFERROR(INDEX('Identificación y Versiones'!$L:$L,MATCH(A2,'Identificación y Versiones'!$A:$A,0)),"")) | S2: =IF(A2="","",COUNTIF('Casos de Prueba'!$B$2:$B$1000,A2)) | T2: =IF(A2="","",COUNTIFS('Casos de Prueba'!$B$2:$B$1000,A2,'Casos de Prueba'!$J$2:$J$1000,"<>Pendiente",'Casos de Prueba'!$J$2:$J$1000,"<>")) | U2: =IF(A2="","",COUNTIFS('Casos de Prueba'!$B$2:$B$1000,A2,'Casos de Prueba'!$J$2:$J$1000,"Aprobado")) | V2: =IF(A2="","",COUNTIFS('Casos de Prueba'!$B$2:$B$1000,A2,'Casos de Prueba'!$J$2:$J$1000,"Fallido")) | W2: =IF(A2="","",COUNTIFS('Casos de Prueba'!$B$2:$B$1000,A2,'Casos de Prueba'!$J$2:$J$1000,"Bloqueado")) | X2: =IF(A2="","",COUNTIFS('Casos de Prueba'!$B$2:$B$1000,A2,'Casos de Prueba'!$J$2:$J$1000,"Pendiente")) | Y2: =IF(A2="","",COUNTIFS(Incidencias!$C$2:$C$1000,A2,Incidencias!$N$2:$N$1000,"<>Cerrado")-COUNTIFS(Incidencias!$C$2:$C$1000,A2,Incidencias!$N$2:$N$1000,"")) | AD2: =IF(A2="","","Resumen de visita — Sesión "&A2&CHAR(10)&"Fecha de la visita: "&C2&CHAR(10)&"Cliente / Comercio: "&D2&CHAR(10)&"Máquina: "&E2&" "&F2&" (Serial: "&G2&")"&CHAR(10)&"POS: "&H2&" (Serial: "&I2&") — Firmware: "&J2&CHAR(10)&"MDB: "&K2&" / "&L2&" / "&M2&CHAR(10)&"Financiera: "&N2&" | Agente Polaris: "&O2&CHAR(10)&"Participantes: "&P2&" (Responsable: "&Q2&")"&CHAR(10)&"Objetivo: "&R2&CHAR(10)&CHAR(10)&"Resultado de pruebas: "&T2&"/"&S2&" ejecutadas — Aprobadas: "&U2&", Fallidas: "&V2&", Bloqueadas: "&W2&", Pendientes: "&X2&CHAR(10)&"Incidencias abiertas: "&Y2&CHAR(10)&CHAR(10)&"Concepto final: "&AB2&CHAR(10)&"Pendientes: "&AA2)
A3: SES-002 | C3: =IF(A3="","",IFERROR(INDEX('Identificación y Versiones'!$B:$B,MATCH(A3,'Identificación y Versiones'!$A:$A,0)),"")) | D3: =IF(A3="","",IFERROR(INDEX('Identificación y Versiones'!$F:$F,MATCH(A3,'Identificación y Versiones'!$A:$A,0)),"")) | E3: =IF(A3="","",IFERROR(INDEX('Identificación y Versiones'!$G:$G,MATCH(A3,'Identificación y Versiones'!$A:$A,0)),"")) | F3: =IF(A3="","",IFERROR(INDEX('Identificación y Versiones'!$H:$H,MATCH(A3,'Identificación y Versiones'!$A:$A,0)),"")) | G3: =IF(A3="","",IFERROR(INDEX('Identificación y Versiones'!$I:$I,MATCH(A3,'Identificación y Versiones'!$A:$A,0)),"")) | H3: =IF(A3="","",IFERROR(INDEX('Identificación y Versiones'!$J:$J,MATCH(A3,'Identificación y Versiones'!$A:$A,0)),"")) | I3: =IF(A3="","",IFERROR(INDEX('Identificación y Versiones'!$K:$K,MATCH(A3,'Identificación y Versiones'!$A:$A,0)),"")) | J3: =IF(A3="","",IFERROR(INDEX('Identificación y Versiones'!$N:$N,MATCH(A3,'Identificación y Versiones'!$A:$A,0)),"")) | K3: =IF(A3="","",IFERROR(INDEX('Identificación y Versiones'!$O:$O,MATCH(A3,'Identificación y Versiones'!$A:$A,0)),"")) | L3: =IF(A3="","",IFERROR(INDEX('Identificación y Versiones'!$P:$P,MATCH(A3,'Identificación y Versiones'!$A:$A,0)),"")) | M3: =IF(A3="","",IFERROR(INDEX('Identificación y Versiones'!$Q:$Q,MATCH(A3,'Identificación y Versiones'!$A:$A,0)),"")) | N3: =IF(A3="","",IFERROR(INDEX('Identificación y Versiones'!$R:$R,MATCH(A3,'Identificación y Versiones'!$A:$A,0)),"")) | O3: =IF(A3="","",IFERROR(INDEX('Identificación y Versiones'!$S:$S,MATCH(A3,'Identificación y Versiones'!$A:$A,0)),"")) | P3: =IF(A3="","",IFERROR(INDEX('Identificación y Versiones'!$E:$E,MATCH(A3,'Identificación y Versiones'!$A:$A,0)),"")) | Q3: =IF(A3="","",IFERROR(INDEX('Identificación y Versiones'!$D:$D,MATCH(A3,'Identificación y Versiones'!$A:$A,0)),"")) | R3: =IF(A3="","",IFERROR(INDEX('Identificación y Versiones'!$L:$L,MATCH(A3,'Identificación y Versiones'!$A:$A,0)),"")) | S3: =IF(A3="","",COUNTIF('Casos de Prueba'!$B$2:$B$1000,A3)) | T3: =IF(A3="","",COUNTIFS('Casos de Prueba'!$B$2:$B$1000,A3,'Casos de Prueba'!$J$2:$J$1000,"<>Pendiente",'Casos de Prueba'!$J$2:$J$1000,"<>")) | U3: =IF(A3="","",COUNTIFS('Casos de Prueba'!$B$2:$B$1000,A3,'Casos de Prueba'!$J$2:$J$1000,"Aprobado")) | V3: =IF(A3="","",COUNTIFS('Casos de Prueba'!$B$2:$B$1000,A3,'Casos de Prueba'!$J$2:$J$1000,"Fallido")) | W3: =IF(A3="","",COUNTIFS('Casos de Prueba'!$B$2:$B$1000,A3,'Casos de Prueba'!$J$2:$J$1000,"Bloqueado")) | X3: =IF(A3="","",COUNTIFS('Casos de Prueba'!$B$2:$B$1000,A3,'Casos de Prueba'!$J$2:$J$1000,"Pendiente")) | Y3: =IF(A3="","",COUNTIFS(Incidencias!$C$2:$C$1000,A3,Incidencias!$N$2:$N$1000,"<>Cerrado")-COUNTIFS(Incidencias!$C$2:$C$1000,A3,Incidencias!$N$2:$N$1000,"")) | AD3: =IF(A3="","","Resumen de visita — Sesión "&A3&CHAR(10)&"Fecha de la visita: "&C3&CHAR(10)&"Cliente / Comercio: "&D3&CHAR(10)&"Máquina: "&E3&" "&F3&" (Serial: "&G3&")"&CHAR(10)&"POS: "&H3&" (Serial: "&I3&") — Firmware: "&J3&CHAR(10)&"MDB: "&K3&" / "&L3&" / "&M3&CHAR(10)&"Financiera: "&N3&" | Agente Polaris: "&O3&CHAR(10)&"Participantes: "&P3&" (Responsable: "&Q3&")"&CHAR(10)&"Objetivo: "&R3&CHAR(10)&CHAR(10)&"Resultado de pruebas: "&T3&"/"&S3&" ejecutadas — Aprobadas: "&U3&", Fallidas: "&V3&", Bloqueadas: "&W3&", Pendientes: "&X3&CHAR(10)&"Incidencias abiertas: "&Y3&CHAR(10)&CHAR(10)&"Concepto final: "&AB3&CHAR(10)&"Pendientes: "&AA3)
A4: SES-003 | C4: =IF(A4="","",IFERROR(INDEX('Identificación y Versiones'!$B:$B,MATCH(A4,'Identificación y Versiones'!$A:$A,0)),"")) | D4: =IF(A4="","",IFERROR(INDEX('Identificación y Versiones'!$F:$F,MATCH(A4,'Identificación y Versiones'!$A:$A,0)),"")) | E4: =IF(A4="","",IFERROR(INDEX('Identificación y Versiones'!$G:$G,MATCH(A4,'Identificación y Versiones'!$A:$A,0)),"")) | F4: =IF(A4="","",IFERROR(INDEX('Identificación y Versiones'!$H:$H,MATCH(A4,'Identificación y Versiones'!$A:$A,0)),"")) | G4: =IF(A4="","",IFERROR(INDEX('Identificación y Versiones'!$I:$I,MATCH(A4,'Identificación y Versiones'!$A:$A,0)),"")) | H4: =IF(A4="","",IFERROR(INDEX('Identificación y Versiones'!$J:$J,MATCH(A4,'Identificación y Versiones'!$A:$A,0)),"")) | I4: =IF(A4="","",IFERROR(INDEX('Identificación y Versiones'!$K:$K,MATCH(A4,'Identificación y Versiones'!$A:$A,0)),"")) | J4: =IF(A4="","",IFERROR(INDEX('Identificación y Versiones'!$N:$N,MATCH(A4,'Identificación y Versiones'!$A:$A,0)),"")) | K4: =IF(A4="","",IFERROR(INDEX('Identificación y Versiones'!$O:$O,MATCH(A4,'Identificación y Versiones'!$A:$A,0)),"")) | L4: =IF(A4="","",IFERROR(INDEX('Identificación y Versiones'!$P:$P,MATCH(A4,'Identificación y Versiones'!$A:$A,0)),"")) | M4: =IF(A4="","",IFERROR(INDEX('Identificación y Versiones'!$Q:$Q,MATCH(A4,'Identificación y Versiones'!$A:$A,0)),"")) | N4: =IF(A4="","",IFERROR(INDEX('Identificación y Versiones'!$R:$R,MATCH(A4,'Identificación y Versiones'!$A:$A,0)),"")) | O4: =IF(A4="","",IFERROR(INDEX('Identificación y Versiones'!$S:$S,MATCH(A4,'Identificación y Versiones'!$A:$A,0)),"")) | P4: =IF(A4="","",IFERROR(INDEX('Identificación y Versiones'!$E:$E,MATCH(A4,'Identificación y Versiones'!$A:$A,0)),"")) | Q4: =IF(A4="","",IFERROR(INDEX('Identificación y Versiones'!$D:$D,MATCH(A4,'Identificación y Versiones'!$A:$A,0)),"")) | R4: =IF(A4="","",IFERROR(INDEX('Identificación y Versiones'!$L:$L,MATCH(A4,'Identificación y Versiones'!$A:$A,0)),"")) | S4: =IF(A4="","",COUNTIF('Casos de Prueba'!$B$2:$B$1000,A4)) | T4: =IF(A4="","",COUNTIFS('Casos de Prueba'!$B$2:$B$1000,A4,'Casos de Prueba'!$J$2:$J$1000,"<>Pendiente",'Casos de Prueba'!$J$2:$J$1000,"<>")) | U4: =IF(A4="","",COUNTIFS('Casos de Prueba'!$B$2:$B$1000,A4,'Casos de Prueba'!$J$2:$J$1000,"Aprobado")) | V4: =IF(A4="","",COUNTIFS('Casos de Prueba'!$B$2:$B$1000,A4,'Casos de Prueba'!$J$2:$J$1000,"Fallido")) | W4: =IF(A4="","",COUNTIFS('Casos de Prueba'!$B$2:$B$1000,A4,'Casos de Prueba'!$J$2:$J$1000,"Bloqueado")) | X4: =IF(A4="","",COUNTIFS('Casos de Prueba'!$B$2:$B$1000,A4,'Casos de Prueba'!$J$2:$J$1000,"Pendiente")) | Y4: =IF(A4="","",COUNTIFS(Incidencias!$C$2:$C$1000,A4,Incidencias!$N$2:$N$1000,"<>Cerrado")-COUNTIFS(Incidencias!$C$2:$C$1000,A4,Incidencias!$N$2:$N$1000,"")) | AD4: =IF(A4="","","Resumen de visita — Sesión "&A4&CHAR(10)&"Fecha de la visita: "&C4&CHAR(10)&"Cliente / Comercio: "&D4&CHAR(10)&"Máquina: "&E4&" "&F4&" (Serial: "&G4&")"&CHAR(10)&"POS: "&H4&" (Serial: "&I4&") — Firmware: "&J4&CHAR(10)&"MDB: "&K4&" / "&L4&" / "&M4&CHAR(10)&"Financiera: "&N4&" | Agente Polaris: "&O4&CHAR(10)&"Participantes: "&P4&" (Responsable: "&Q4&")"&CHAR(10)&"Objetivo: "&R4&CHAR(10)&CHAR(10)&"Resultado de pruebas: "&T4&"/"&S4&" ejecutadas — Aprobadas: "&U4&", Fallidas: "&V4&", Bloqueadas: "&W4&", Pendientes: "&X4&CHAR(10)&"Incidencias abiertas: "&Y4&CHAR(10)&CHAR(10)&"Concepto final: "&AB4&CHAR(10)&"Pendientes: "&AA4)
C5: =IF(A5="","",IFERROR(INDEX('Identificación y Versiones'!$B:$B,MATCH(A5,'Identificación y Versiones'!$A:$A,0)),"")) | D5: =IF(A5="","",IFERROR(INDEX('Identificación y Versiones'!$F:$F,MATCH(A5,'Identificación y Versiones'!$A:$A,0)),"")) | E5: =IF(A5="","",IFERROR(INDEX('Identificación y Versiones'!$G:$G,MATCH(A5,'Identificación y Versiones'!$A:$A,0)),"")) | F5: =IF(A5="","",IFERROR(INDEX('Identificación y Versiones'!$H:$H,MATCH(A5,'Identificación y Versiones'!$A:$A,0)),"")) | G5: =IF(A5="","",IFERROR(INDEX('Identificación y Versiones'!$I:$I,MATCH(A5,'Identificación y Versiones'!$A:$A,0)),"")) | H5: =IF(A5="","",IFERROR(INDEX('Identificación y Versiones'!$J:$J,MATCH(A5,'Identificación y Versiones'!$A:$A,0)),"")) | I5: =IF(A5="","",IFERROR(INDEX('Identificación y Versiones'!$K:$K,MATCH(A5,'Identificación y Versiones'!$A:$A,0)),"")) | J5: =IF(A5="","",IFERROR(INDEX('Identificación y Versiones'!$N:$N,MATCH(A5,'Identificación y Versiones'!$A:$A,0)),"")) | K5: =IF(A5="","",IFERROR(INDEX('Identificación y Versiones'!$O:$O,MATCH(A5,'Identificación y Versiones'!$A:$A,0)),"")) | L5: =IF(A5="","",IFERROR(INDEX('Identificación y Versiones'!$P:$P,MATCH(A5,'Identificación y Versiones'!$A:$A,0)),"")) | M5: =IF(A5="","",IFERROR(INDEX('Identificación y Versiones'!$Q:$Q,MATCH(A5,'Identificación y Versiones'!$A:$A,0)),"")) | N5: =IF(A5="","",IFERROR(INDEX('Identificación y Versiones'!$R:$R,MATCH(A5,'Identificación y Versiones'!$A:$A,0)),"")) | O5: =IF(A5="","",IFERROR(INDEX('Identificación y Versiones'!$S:$S,MATCH(A5,'Identificación y Versiones'!$A:$A,0)),"")) | P5: =IF(A5="","",IFERROR(INDEX('Identificación y Versiones'!$E:$E,MATCH(A5,'Identificación y Versiones'!$A:$A,0)),"")) | Q5: =IF(A5="","",IFERROR(INDEX('Identificación y Versiones'!$D:$D,MATCH(A5,'Identificación y Versiones'!$A:$A,0)),"")) | R5: =IF(A5="","",IFERROR(INDEX('Identificación y Versiones'!$L:$L,MATCH(A5,'Identificación y Versiones'!$A:$A,0)),"")) | S5: =IF(A5="","",COUNTIF('Casos de Prueba'!$B$2:$B$1000,A5)) | T5: =IF(A5="","",COUNTIFS('Casos de Prueba'!$B$2:$B$1000,A5,'Casos de Prueba'!$J$2:$J$1000,"<>Pendiente",'Casos de Prueba'!$J$2:$J$1000,"<>")) | U5: =IF(A5="","",COUNTIFS('Casos de Prueba'!$B$2:$B$1000,A5,'Casos de Prueba'!$J$2:$J$1000,"Aprobado")) | V5: =IF(A5="","",COUNTIFS('Casos de Prueba'!$B$2:$B$1000,A5,'Casos de Prueba'!$J$2:$J$1000,"Fallido")) | W5: =IF(A5="","",COUNTIFS('Casos de Prueba'!$B$2:$B$1000,A5,'Casos de Prueba'!$J$2:$J$1000,"Bloqueado")) | X5: =IF(A5="","",COUNTIFS('Casos de Prueba'!$B$2:$B$1000,A5,'Casos de Prueba'!$J$2:$J$1000,"Pendiente")) | Y5: =IF(A5="","",COUNTIFS(Incidencias!$C$2:$C$1000,A5,Incidencias!$N$2:$N$1000,"<>Cerrado")-COUNTIFS(Incidencias!$C$2:$C$1000,A5,Incidencias!$N$2:$N$1000,"")) | AD5: =IF(A5="","","Resumen de visita — Sesión "&A5&CHAR(10)&"Fecha de la visita: "&C5&CHAR(10)&"Cliente / Comercio: "&D5&CHAR(10)&"Máquina: "&E5&" "&F5&" (Serial: "&G5&")"&CHAR(10)&"POS: "&H5&" (Serial: "&I5&") — Firmware: "&J5&CHAR(10)&"MDB: "&K5&" / "&L5&" / "&M5&CHAR(10)&"Financiera: "&N5&" | Agente Polaris: "&O5&CHAR(10)&"Participantes: "&P5&" (Responsable: "&Q5&")"&CHAR(10)&"Objetivo: "&R5&CHAR(10)&CHAR(10)&"Resultado de pruebas: "&T5&"/"&S5&" ejecutadas — Aprobadas: "&U5&", Fallidas: "&V5&", Bloqueadas: "&W5&", Pendientes: "&X5&CHAR(10)&"Incidencias abiertas: "&Y5&CHAR(10)&CHAR(10)&"Concepto final: "&AB5&CHAR(10)&"Pendientes: "&AA5)
C6: =IF(A6="","",IFERROR(INDEX('Identificación y Versiones'!$B:$B,MATCH(A6,'Identificación y Versiones'!$A:$A,0)),"")) | D6: =IF(A6="","",IFERROR(INDEX('Identificación y Versiones'!$F:$F,MATCH(A6,'Identificación y Versiones'!$A:$A,0)),"")) | E6: =IF(A6="","",IFERROR(INDEX('Identificación y Versiones'!$G:$G,MATCH(A6,'Identificación y Versiones'!$A:$A,0)),"")) | F6: =IF(A6="","",IFERROR(INDEX('Identificación y Versiones'!$H:$H,MATCH(A6,'Identificación y Versiones'!$A:$A,0)),"")) | G6: =IF(A6="","",IFERROR(INDEX('Identificación y Versiones'!$I:$I,MATCH(A6,'Identificación y Versiones'!$A:$A,0)),"")) | H6: =IF(A6="","",IFERROR(INDEX('Identificación y Versiones'!$J:$J,MATCH(A6,'Identificación y Versiones'!$A:$A,0)),"")) | I6: =IF(A6="","",IFERROR(INDEX('Identificación y Versiones'!$K:$K,MATCH(A6,'Identificación y Versiones'!$A:$A,0)),"")) | J6: =IF(A6="","",IFERROR(INDEX('Identificación y Versiones'!$N:$N,MATCH(A6,'Identificación y Versiones'!$A:$A,0)),"")) | K6: =IF(A6="","",IFERROR(INDEX('Identificación y Versiones'!$O:$O,MATCH(A6,'Identificación y Versiones'!$A:$A,0)),"")) | L6: =IF(A6="","",IFERROR(INDEX('Identificación y Versiones'!$P:$P,MATCH(A6,'Identificación y Versiones'!$A:$A,0)),"")) | M6: =IF(A6="","",IFERROR(INDEX('Identificación y Versiones'!$Q:$Q,MATCH(A6,'Identificación y Versiones'!$A:$A,0)),"")) | N6: =IF(A6="","",IFERROR(INDEX('Identificación y Versiones'!$R:$R,MATCH(A6,'Identificación y Versiones'!$A:$A,0)),"")) | O6: =IF(A6="","",IFERROR(INDEX('Identificación y Versiones'!$S:$S,MATCH(A6,'Identificación y Versiones'!$A:$A,0)),"")) | P6: =IF(A6="","",IFERROR(INDEX('Identificación y Versiones'!$E:$E,MATCH(A6,'Identificación y Versiones'!$A:$A,0)),"")) | Q6: =IF(A6="","",IFERROR(INDEX('Identificación y Versiones'!$D:$D,MATCH(A6,'Identificación y Versiones'!$A:$A,0)),"")) | R6: =IF(A6="","",IFERROR(INDEX('Identificación y Versiones'!$L:$L,MATCH(A6,'Identificación y Versiones'!$A:$A,0)),"")) | S6: =IF(A6="","",COUNTIF('Casos de Prueba'!$B$2:$B$1000,A6)) | T6: =IF(A6="","",COUNTIFS('Casos de Prueba'!$B$2:$B$1000,A6,'Casos de Prueba'!$J$2:$J$1000,"<>Pendiente",'Casos de Prueba'!$J$2:$J$1000,"<>")) | U6: =IF(A6="","",COUNTIFS('Casos de Prueba'!$B$2:$B$1000,A6,'Casos de Prueba'!$J$2:$J$1000,"Aprobado")) | V6: =IF(A6="","",COUNTIFS('Casos de Prueba'!$B$2:$B$1000,A6,'Casos de Prueba'!$J$2:$J$1000,"Fallido")) | W6: =IF(A6="","",COUNTIFS('Casos de Prueba'!$B$2:$B$1000,A6,'Casos de Prueba'!$J$2:$J$1000,"Bloqueado")) | X6: =IF(A6="","",COUNTIFS('Casos de Prueba'!$B$2:$B$1000,A6,'Casos de Prueba'!$J$2:$J$1000,"Pendiente")) | Y6: =IF(A6="","",COUNTIFS(Incidencias!$C$2:$C$1000,A6,Incidencias!$N$2:$N$1000,"<>Cerrado")-COUNTIFS(Incidencias!$C$2:$C$1000,A6,Incidencias!$N$2:$N$1000,"")) | AD6: =IF(A6="","","Resumen de visita — Sesión "&A6&CHAR(10)&"Fecha de la visita: "&C6&CHAR(10)&"Cliente / Comercio: "&D6&CHAR(10)&"Máquina: "&E6&" "&F6&" (Serial: "&G6&")"&CHAR(10)&"POS: "&H6&" (Serial: "&I6&") — Firmware: "&J6&CHAR(10)&"MDB: "&K6&" / "&L6&" / "&M6&CHAR(10)&"Financiera: "&N6&" | Agente Polaris: "&O6&CHAR(10)&"Participantes: "&P6&" (Responsable: "&Q6&")"&CHAR(10)&"Objetivo: "&R6&CHAR(10)&CHAR(10)&"Resultado de pruebas: "&T6&"/"&S6&" ejecutadas — Aprobadas: "&U6&", Fallidas: "&V6&", Bloqueadas: "&W6&", Pendientes: "&X6&CHAR(10)&"Incidencias abiertas: "&Y6&CHAR(10)&CHAR(10)&"Concepto final: "&AB6&CHAR(10)&"Pendientes: "&AA6)
C7: =IF(A7="","",IFERROR(INDEX('Identificación y Versiones'!$B:$B,MATCH(A7,'Identificación y Versiones'!$A:$A,0)),"")) | D7: =IF(A7="","",IFERROR(INDEX('Identificación y Versiones'!$F:$F,MATCH(A7,'Identificación y Versiones'!$A:$A,0)),"")) | E7: =IF(A7="","",IFERROR(INDEX('Identificación y Versiones'!$G:$G,MATCH(A7,'Identificación y Versiones'!$A:$A,0)),"")) | F7: =IF(A7="","",IFERROR(INDEX('Identificación y Versiones'!$H:$H,MATCH(A7,'Identificación y Versiones'!$A:$A,0)),"")) | G7: =IF(A7="","",IFERROR(INDEX('Identificación y Versiones'!$I:$I,MATCH(A7,'Identificación y Versiones'!$A:$A,0)),"")) | H7: =IF(A7="","",IFERROR(INDEX('Identificación y Versiones'!$J:$J,MATCH(A7,'Identificación y Versiones'!$A:$A,0)),"")) | I7: =IF(A7="","",IFERROR(INDEX('Identificación y Versiones'!$K:$K,MATCH(A7,'Identificación y Versiones'!$A:$A,0)),"")) | J7: =IF(A7="","",IFERROR(INDEX('Identificación y Versiones'!$N:$N,MATCH(A7,'Identificación y Versiones'!$A:$A,0)),"")) | K7: =IF(A7="","",IFERROR(INDEX('Identificación y Versiones'!$O:$O,MATCH(A7,'Identificación y Versiones'!$A:$A,0)),"")) | L7: =IF(A7="","",IFERROR(INDEX('Identificación y Versiones'!$P:$P,MATCH(A7,'Identificación y Versiones'!$A:$A,0)),"")) | M7: =IF(A7="","",IFERROR(INDEX('Identificación y Versiones'!$Q:$Q,MATCH(A7,'Identificación y Versiones'!$A:$A,0)),"")) | N7: =IF(A7="","",IFERROR(INDEX('Identificación y Versiones'!$R:$R,MATCH(A7,'Identificación y Versiones'!$A:$A,0)),"")) | O7: =IF(A7="","",IFERROR(INDEX('Identificación y Versiones'!$S:$S,MATCH(A7,'Identificación y Versiones'!$A:$A,0)),"")) | P7: =IF(A7="","",IFERROR(INDEX('Identificación y Versiones'!$E:$E,MATCH(A7,'Identificación y Versiones'!$A:$A,0)),"")) | Q7: =IF(A7="","",IFERROR(INDEX('Identificación y Versiones'!$D:$D,MATCH(A7,'Identificación y Versiones'!$A:$A,0)),"")) | R7: =IF(A7="","",IFERROR(INDEX('Identificación y Versiones'!$L:$L,MATCH(A7,'Identificación y Versiones'!$A:$A,0)),"")) | S7: =IF(A7="","",COUNTIF('Casos de Prueba'!$B$2:$B$1000,A7)) | T7: =IF(A7="","",COUNTIFS('Casos de Prueba'!$B$2:$B$1000,A7,'Casos de Prueba'!$J$2:$J$1000,"<>Pendiente",'Casos de Prueba'!$J$2:$J$1000,"<>")) | U7: =IF(A7="","",COUNTIFS('Casos de Prueba'!$B$2:$B$1000,A7,'Casos de Prueba'!$J$2:$J$1000,"Aprobado")) | V7: =IF(A7="","",COUNTIFS('Casos de Prueba'!$B$2:$B$1000,A7,'Casos de Prueba'!$J$2:$J$1000,"Fallido")) | W7: =IF(A7="","",COUNTIFS('Casos de Prueba'!$B$2:$B$1000,A7,'Casos de Prueba'!$J$2:$J$1000,"Bloqueado")) | X7: =IF(A7="","",COUNTIFS('Casos de Prueba'!$B$2:$B$1000,A7,'Casos de Prueba'!$J$2:$J$1000,"Pendiente")) | Y7: =IF(A7="","",COUNTIFS(Incidencias!$C$2:$C$1000,A7,Incidencias!$N$2:$N$1000,"<>Cerrado")-COUNTIFS(Incidencias!$C$2:$C$1000,A7,Incidencias!$N$2:$N$1000,"")) | AD7: =IF(A7="","","Resumen de visita — Sesión "&A7&CHAR(10)&"Fecha de la visita: "&C7&CHAR(10)&"Cliente / Comercio: "&D7&CHAR(10)&"Máquina: "&E7&" "&F7&" (Serial: "&G7&")"&CHAR(10)&"POS: "&H7&" (Serial: "&I7&") — Firmware: "&J7&CHAR(10)&"MDB: "&K7&" / "&L7&" / "&M7&CHAR(10)&"Financiera: "&N7&" | Agente Polaris: "&O7&CHAR(10)&"Participantes: "&P7&" (Responsable: "&Q7&")"&CHAR(10)&"Objetivo: "&R7&CHAR(10)&CHAR(10)&"Resultado de pruebas: "&T7&"/"&S7&" ejecutadas — Aprobadas: "&U7&", Fallidas: "&V7&", Bloqueadas: "&W7&", Pendientes: "&X7&CHAR(10)&"Incidencias abiertas: "&Y7&CHAR(10)&CHAR(10)&"Concepto final: "&AB7&CHAR(10)&"Pendientes: "&AA7)
C8: =IF(A8="","",IFERROR(INDEX('Identificación y Versiones'!$B:$B,MATCH(A8,'Identificación y Versiones'!$A:$A,0)),"")) | D8: =IF(A8="","",IFERROR(INDEX('Identificación y Versiones'!$F:$F,MATCH(A8,'Identificación y Versiones'!$A:$A,0)),"")) | E8: =IF(A8="","",IFERROR(INDEX('Identificación y Versiones'!$G:$G,MATCH(A8,'Identificación y Versiones'!$A:$A,0)),"")) | F8: =IF(A8="","",IFERROR(INDEX('Identificación y Versiones'!$H:$H,MATCH(A8,'Identificación y Versiones'!$A:$A,0)),"")) | G8: =IF(A8="","",IFERROR(INDEX('Identificación y Versiones'!$I:$I,MATCH(A8,'Identificación y Versiones'!$A:$A,0)),"")) | H8: =IF(A8="","",IFERROR(INDEX('Identificación y Versiones'!$J:$J,MATCH(A8,'Identificación y Versiones'!$A:$A,0)),"")) | I8: =IF(A8="","",IFERROR(INDEX('Identificación y Versiones'!$K:$K,MATCH(A8,'Identificación y Versiones'!$A:$A,0)),"")) | J8: =IF(A8="","",IFERROR(INDEX('Identificación y Versiones'!$N:$N,MATCH(A8,'Identificación y Versiones'!$A:$A,0)),"")) | K8: =IF(A8="","",IFERROR(INDEX('Identificación y Versiones'!$O:$O,MATCH(A8,'Identificación y Versiones'!$A:$A,0)),"")) | L8: =IF(A8="","",IFERROR(INDEX('Identificación y Versiones'!$P:$P,MATCH(A8,'Identificación y Versiones'!$A:$A,0)),"")) | M8: =IF(A8="","",IFERROR(INDEX('Identificación y Versiones'!$Q:$Q,MATCH(A8,'Identificación y Versiones'!$A:$A,0)),"")) | N8: =IF(A8="","",IFERROR(INDEX('Identificación y Versiones'!$R:$R,MATCH(A8,'Identificación y Versiones'!$A:$A,0)),"")) | O8: =IF(A8="","",IFERROR(INDEX('Identificación y Versiones'!$S:$S,MATCH(A8,'Identificación y Versiones'!$A:$A,0)),"")) | P8: =IF(A8="","",IFERROR(INDEX('Identificación y Versiones'!$E:$E,MATCH(A8,'Identificación y Versiones'!$A:$A,0)),"")) | Q8: =IF(A8="","",IFERROR(INDEX('Identificación y Versiones'!$D:$D,MATCH(A8,'Identificación y Versiones'!$A:$A,0)),"")) | R8: =IF(A8="","",IFERROR(INDEX('Identificación y Versiones'!$L:$L,MATCH(A8,'Identificación y Versiones'!$A:$A,0)),"")) | S8: =IF(A8="","",COUNTIF('Casos de Prueba'!$B$2:$B$1000,A8)) | T8: =IF(A8="","",COUNTIFS('Casos de Prueba'!$B$2:$B$1000,A8,'Casos de Prueba'!$J$2:$J$1000,"<>Pendiente",'Casos de Prueba'!$J$2:$J$1000,"<>")) | U8: =IF(A8="","",COUNTIFS('Casos de Prueba'!$B$2:$B$1000,A8,'Casos de Prueba'!$J$2:$J$1000,"Aprobado")) | V8: =IF(A8="","",COUNTIFS('Casos de Prueba'!$B$2:$B$1000,A8,'Casos de Prueba'!$J$2:$J$1000,"Fallido")) | W8: =IF(A8="","",COUNTIFS('Casos de Prueba'!$B$2:$B$1000,A8,'Casos de Prueba'!$J$2:$J$1000,"Bloqueado")) | X8: =IF(A8="","",COUNTIFS('Casos de Prueba'!$B$2:$B$1000,A8,'Casos de Prueba'!$J$2:$J$1000,"Pendiente")) | Y8: =IF(A8="","",COUNTIFS(Incidencias!$C$2:$C$1000,A8,Incidencias!$N$2:$N$1000,"<>Cerrado")-COUNTIFS(Incidencias!$C$2:$C$1000,A8,Incidencias!$N$2:$N$1000,"")) | AD8: =IF(A8="","","Resumen de visita — Sesión "&A8&CHAR(10)&"Fecha de la visita: "&C8&CHAR(10)&"Cliente / Comercio: "&D8&CHAR(10)&"Máquina: "&E8&" "&F8&" (Serial: "&G8&")"&CHAR(10)&"POS: "&H8&" (Serial: "&I8&") — Firmware: "&J8&CHAR(10)&"MDB: "&K8&" / "&L8&" / "&M8&CHAR(10)&"Financiera: "&N8&" | Agente Polaris: "&O8&CHAR(10)&"Participantes: "&P8&" (Responsable: "&Q8&")"&CHAR(10)&"Objetivo: "&R8&CHAR(10)&CHAR(10)&"Resultado de pruebas: "&T8&"/"&S8&" ejecutadas — Aprobadas: "&U8&", Fallidas: "&V8&", Bloqueadas: "&W8&", Pendientes: "&X8&CHAR(10)&"Incidencias abiertas: "&Y8&CHAR(10)&CHAR(10)&"Concepto final: "&AB8&CHAR(10)&"Pendientes: "&AA8)
C9: =IF(A9="","",IFERROR(INDEX('Identificación y Versiones'!$B:$B,MATCH(A9,'Identificación y Versiones'!$A:$A,0)),"")) | D9: =IF(A9="","",IFERROR(INDEX('Identificación y Versiones'!$F:$F,MATCH(A9,'Identificación y Versiones'!$A:$A,0)),"")) | E9: =IF(A9="","",IFERROR(INDEX('Identificación y Versiones'!$G:$G,MATCH(A9,'Identificación y Versiones'!$A:$A,0)),"")) | F9: =IF(A9="","",IFERROR(INDEX('Identificación y Versiones'!$H:$H,MATCH(A9,'Identificación y Versiones'!$A:$A,0)),"")) | G9: =IF(A9="","",IFERROR(INDEX('Identificación y Versiones'!$I:$I,MATCH(A9,'Identificación y Versiones'!$A:$A,0)),"")) | H9: =IF(A9="","",IFERROR(INDEX('Identificación y Versiones'!$J:$J,MATCH(A9,'Identificación y Versiones'!$A:$A,0)),"")) | I9: =IF(A9="","",IFERROR(INDEX('Identificación y Versiones'!$K:$K,MATCH(A9,'Identificación y Versiones'!$A:$A,0)),"")) | J9: =IF(A9="","",IFERROR(INDEX('Identificación y Versiones'!$N:$N,MATCH(A9,'Identificación y Versiones'!$A:$A,0)),"")) | K9: =IF(A9="","",IFERROR(INDEX('Identificación y Versiones'!$O:$O,MATCH(A9,'Identificación y Versiones'!$A:$A,0)),"")) | L9: =IF(A9="","",IFERROR(INDEX('Identificación y Versiones'!$P:$P,MATCH(A9,'Identificación y Versiones'!$A:$A,0)),"")) | M9: =IF(A9="","",IFERROR(INDEX('Identificación y Versiones'!$Q:$Q,MATCH(A9,'Identificación y Versiones'!$A:$A,0)),"")) | N9: =IF(A9="","",IFERROR(INDEX('Identificación y Versiones'!$R:$R,MATCH(A9,'Identificación y Versiones'!$A:$A,0)),"")) | O9: =IF(A9="","",IFERROR(INDEX('Identificación y Versiones'!$S:$S,MATCH(A9,'Identificación y Versiones'!$A:$A,0)),"")) | P9: =IF(A9="","",IFERROR(INDEX('Identificación y Versiones'!$E:$E,MATCH(A9,'Identificación y Versiones'!$A:$A,0)),"")) | Q9: =IF(A9="","",IFERROR(INDEX('Identificación y Versiones'!$D:$D,MATCH(A9,'Identificación y Versiones'!$A:$A,0)),"")) | R9: =IF(A9="","",IFERROR(INDEX('Identificación y Versiones'!$L:$L,MATCH(A9,'Identificación y Versiones'!$A:$A,0)),"")) | S9: =IF(A9="","",COUNTIF('Casos de Prueba'!$B$2:$B$1000,A9)) | T9: =IF(A9="","",COUNTIFS('Casos de Prueba'!$B$2:$B$1000,A9,'Casos de Prueba'!$J$2:$J$1000,"<>Pendiente",'Casos de Prueba'!$J$2:$J$1000,"<>")) | U9: =IF(A9="","",COUNTIFS('Casos de Prueba'!$B$2:$B$1000,A9,'Casos de Prueba'!$J$2:$J$1000,"Aprobado")) | V9: =IF(A9="","",COUNTIFS('Casos de Prueba'!$B$2:$B$1000,A9,'Casos de Prueba'!$J$2:$J$1000,"Fallido")) | W9: =IF(A9="","",COUNTIFS('Casos de Prueba'!$B$2:$B$1000,A9,'Casos de Prueba'!$J$2:$J$1000,"Bloqueado")) | X9: =IF(A9="","",COUNTIFS('Casos de Prueba'!$B$2:$B$1000,A9,'Casos de Prueba'!$J$2:$J$1000,"Pendiente")) | Y9: =IF(A9="","",COUNTIFS(Incidencias!$C$2:$C$1000,A9,Incidencias!$N$2:$N$1000,"<>Cerrado")-COUNTIFS(Incidencias!$C$2:$C$1000,A9,Incidencias!$N$2:$N$1000,"")) | AD9: =IF(A9="","","Resumen de visita — Sesión "&A9&CHAR(10)&"Fecha de la visita: "&C9&CHAR(10)&"Cliente / Comercio: "&D9&CHAR(10)&"Máquina: "&E9&" "&F9&" (Serial: "&G9&")"&CHAR(10)&"POS: "&H9&" (Serial: "&I9&") — Firmware: "&J9&CHAR(10)&"MDB: "&K9&" / "&L9&" / "&M9&CHAR(10)&"Financiera: "&N9&" | Agente Polaris: "&O9&CHAR(10)&"Participantes: "&P9&" (Responsable: "&Q9&")"&CHAR(10)&"Objetivo: "&R9&CHAR(10)&CHAR(10)&"Resultado de pruebas: "&T9&"/"&S9&" ejecutadas — Aprobadas: "&U9&", Fallidas: "&V9&", Bloqueadas: "&W9&", Pendientes: "&X9&CHAR(10)&"Incidencias abiertas: "&Y9&CHAR(10)&CHAR(10)&"Concepto final: "&AB9&CHAR(10)&"Pendientes: "&AA9)
C10: =IF(A10="","",IFERROR(INDEX('Identificación y Versiones'!$B:$B,MATCH(A10,'Identificación y Versiones'!$A:$A,0)),"")) | D10: =IF(A10="","",IFERROR(INDEX('Identificación y Versiones'!$F:$F,MATCH(A10,'Identificación y Versiones'!$A:$A,0)),"")) | E10: =IF(A10="","",IFERROR(INDEX('Identificación y Versiones'!$G:$G,MATCH(A10,'Identificación y Versiones'!$A:$A,0)),"")) | F10: =IF(A10="","",IFERROR(INDEX('Identificación y Versiones'!$H:$H,MATCH(A10,'Identificación y Versiones'!$A:$A,0)),"")) | G10: =IF(A10="","",IFERROR(INDEX('Identificación y Versiones'!$I:$I,MATCH(A10,'Identificación y Versiones'!$A:$A,0)),"")) | H10: =IF(A10="","",IFERROR(INDEX('Identificación y Versiones'!$J:$J,MATCH(A10,'Identificación y Versiones'!$A:$A,0)),"")) | I10: =IF(A10="","",IFERROR(INDEX('Identificación y Versiones'!$K:$K,MATCH(A10,'Identificación y Versiones'!$A:$A,0)),"")) | J10: =IF(A10="","",IFERROR(INDEX('Identificación y Versiones'!$N:$N,MATCH(A10,'Identificación y Versiones'!$A:$A,0)),"")) | K10: =IF(A10="","",IFERROR(INDEX('Identificación y Versiones'!$O:$O,MATCH(A10,'Identificación y Versiones'!$A:$A,0)),"")) | L10: =IF(A10="","",IFERROR(INDEX('Identificación y Versiones'!$P:$P,MATCH(A10,'Identificación y Versiones'!$A:$A,0)),"")) | M10: =IF(A10="","",IFERROR(INDEX('Identificación y Versiones'!$Q:$Q,MATCH(A10,'Identificación y Versiones'!$A:$A,0)),"")) | N10: =IF(A10="","",IFERROR(INDEX('Identificación y Versiones'!$R:$R,MATCH(A10,'Identificación y Versiones'!$A:$A,0)),"")) | O10: =IF(A10="","",IFERROR(INDEX('Identificación y Versiones'!$S:$S,MATCH(A10,'Identificación y Versiones'!$A:$A,0)),"")) | P10: =IF(A10="","",IFERROR(INDEX('Identificación y Versiones'!$E:$E,MATCH(A10,'Identificación y Versiones'!$A:$A,0)),"")) | Q10: =IF(A10="","",IFERROR(INDEX('Identificación y Versiones'!$D:$D,MATCH(A10,'Identificación y Versiones'!$A:$A,0)),"")) | R10: =IF(A10="","",IFERROR(INDEX('Identificación y Versiones'!$L:$L,MATCH(A10,'Identificación y Versiones'!$A:$A,0)),"")) | S10: =IF(A10="","",COUNTIF('Casos de Prueba'!$B$2:$B$1000,A10)) | T10: =IF(A10="","",COUNTIFS('Casos de Prueba'!$B$2:$B$1000,A10,'Casos de Prueba'!$J$2:$J$1000,"<>Pendiente",'Casos de Prueba'!$J$2:$J$1000,"<>")) | U10: =IF(A10="","",COUNTIFS('Casos de Prueba'!$B$2:$B$1000,A10,'Casos de Prueba'!$J$2:$J$1000,"Aprobado")) | V10: =IF(A10="","",COUNTIFS('Casos de Prueba'!$B$2:$B$1000,A10,'Casos de Prueba'!$J$2:$J$1000,"Fallido")) | W10: =IF(A10="","",COUNTIFS('Casos de Prueba'!$B$2:$B$1000,A10,'Casos de Prueba'!$J$2:$J$1000,"Bloqueado")) | X10: =IF(A10="","",COUNTIFS('Casos de Prueba'!$B$2:$B$1000,A10,'Casos de Prueba'!$J$2:$J$1000,"Pendiente")) | Y10: =IF(A10="","",COUNTIFS(Incidencias!$C$2:$C$1000,A10,Incidencias!$N$2:$N$1000,"<>Cerrado")-COUNTIFS(Incidencias!$C$2:$C$1000,A10,Incidencias!$N$2:$N$1000,"")) | AD10: =IF(A10="","","Resumen de visita — Sesión "&A10&CHAR(10)&"Fecha de la visita: "&C10&CHAR(10)&"Cliente / Comercio: "&D10&CHAR(10)&"Máquina: "&E10&" "&F10&" (Serial: "&G10&")"&CHAR(10)&"POS: "&H10&" (Serial: "&I10&") — Firmware: "&J10&CHAR(10)&"MDB: "&K10&" / "&L10&" / "&M10&CHAR(10)&"Financiera: "&N10&" | Agente Polaris: "&O10&CHAR(10)&"Participantes: "&P10&" (Responsable: "&Q10&")"&CHAR(10)&"Objetivo: "&R10&CHAR(10)&CHAR(10)&"Resultado de pruebas: "&T10&"/"&S10&" ejecutadas — Aprobadas: "&U10&", Fallidas: "&V10&", Bloqueadas: "&W10&", Pendientes: "&X10&CHAR(10)&"Incidencias abiertas: "&Y10&CHAR(10)&CHAR(10)&"Concepto final: "&AB10&CHAR(10)&"Pendientes: "&AA10)
C11: =IF(A11="","",IFERROR(INDEX('Identificación y Versiones'!$B:$B,MATCH(A11,'Identificación y Versiones'!$A:$A,0)),"")) | D11: =IF(A11="","",IFERROR(INDEX('Identificación y Versiones'!$F:$F,MATCH(A11,'Identificación y Versiones'!$A:$A,0)),"")) | E11: =IF(A11="","",IFERROR(INDEX('Identificación y Versiones'!$G:$G,MATCH(A11,'Identificación y Versiones'!$A:$A,0)),"")) | F11: =IF(A11="","",IFERROR(INDEX('Identificación y Versiones'!$H:$H,MATCH(A11,'Identificación y Versiones'!$A:$A,0)),"")) | G11: =IF(A11="","",IFERROR(INDEX('Identificación y Versiones'!$I:$I,MATCH(A11,'Identificación y Versiones'!$A:$A,0)),"")) | H11: =IF(A11="","",IFERROR(INDEX('Identificación y Versiones'!$J:$J,MATCH(A11,'Identificación y Versiones'!$A:$A,0)),"")) | I11: =IF(A11="","",IFERROR(INDEX('Identificación y Versiones'!$K:$K,MATCH(A11,'Identificación y Versiones'!$A:$A,0)),"")) | J11: =IF(A11="","",IFERROR(INDEX('Identificación y Versiones'!$N:$N,MATCH(A11,'Identificación y Versiones'!$A:$A,0)),"")) | K11: =IF(A11="","",IFERROR(INDEX('Identificación y Versiones'!$O:$O,MATCH(A11,'Identificación y Versiones'!$A:$A,0)),"")) | L11: =IF(A11="","",IFERROR(INDEX('Identificación y Versiones'!$P:$P,MATCH(A11,'Identificación y Versiones'!$A:$A,0)),"")) | M11: =IF(A11="","",IFERROR(INDEX('Identificación y Versiones'!$Q:$Q,MATCH(A11,'Identificación y Versiones'!$A:$A,0)),"")) | N11: =IF(A11="","",IFERROR(INDEX('Identificación y Versiones'!$R:$R,MATCH(A11,'Identificación y Versiones'!$A:$A,0)),"")) | O11: =IF(A11="","",IFERROR(INDEX('Identificación y Versiones'!$S:$S,MATCH(A11,'Identificación y Versiones'!$A:$A,0)),"")) | P11: =IF(A11="","",IFERROR(INDEX('Identificación y Versiones'!$E:$E,MATCH(A11,'Identificación y Versiones'!$A:$A,0)),"")) | Q11: =IF(A11="","",IFERROR(INDEX('Identificación y Versiones'!$D:$D,MATCH(A11,'Identificación y Versiones'!$A:$A,0)),"")) | R11: =IF(A11="","",IFERROR(INDEX('Identificación y Versiones'!$L:$L,MATCH(A11,'Identificación y Versiones'!$A:$A,0)),"")) | S11: =IF(A11="","",COUNTIF('Casos de Prueba'!$B$2:$B$1000,A11)) | T11: =IF(A11="","",COUNTIFS('Casos de Prueba'!$B$2:$B$1000,A11,'Casos de Prueba'!$J$2:$J$1000,"<>Pendiente",'Casos de Prueba'!$J$2:$J$1000,"<>")) | U11: =IF(A11="","",COUNTIFS('Casos de Prueba'!$B$2:$B$1000,A11,'Casos de Prueba'!$J$2:$J$1000,"Aprobado")) | V11: =IF(A11="","",COUNTIFS('Casos de Prueba'!$B$2:$B$1000,A11,'Casos de Prueba'!$J$2:$J$1000,"Fallido")) | W11: =IF(A11="","",COUNTIFS('Casos de Prueba'!$B$2:$B$1000,A11,'Casos de Prueba'!$J$2:$J$1000,"Bloqueado")) | X11: =IF(A11="","",COUNTIFS('Casos de Prueba'!$B$2:$B$1000,A11,'Casos de Prueba'!$J$2:$J$1000,"Pendiente")) | Y11: =IF(A11="","",COUNTIFS(Incidencias!$C$2:$C$1000,A11,Incidencias!$N$2:$N$1000,"<>Cerrado")-COUNTIFS(Incidencias!$C$2:$C$1000,A11,Incidencias!$N$2:$N$1000,"")) | AD11: =IF(A11="","","Resumen de visita — Sesión "&A11&CHAR(10)&"Fecha de la visita: "&C11&CHAR(10)&"Cliente / Comercio: "&D11&CHAR(10)&"Máquina: "&E11&" "&F11&" (Serial: "&G11&")"&CHAR(10)&"POS: "&H11&" (Serial: "&I11&") — Firmware: "&J11&CHAR(10)&"MDB: "&K11&" / "&L11&" / "&M11&CHAR(10)&"Financiera: "&N11&" | Agente Polaris: "&O11&CHAR(10)&"Participantes: "&P11&" (Responsable: "&Q11&")"&CHAR(10)&"Objetivo: "&R11&CHAR(10)&CHAR(10)&"Resultado de pruebas: "&T11&"/"&S11&" ejecutadas — Aprobadas: "&U11&", Fallidas: "&V11&", Bloqueadas: "&W11&", Pendientes: "&X11&CHAR(10)&"Incidencias abiertas: "&Y11&CHAR(10)&CHAR(10)&"Concepto final: "&AB11&CHAR(10)&"Pendientes: "&AA11)
C12: =IF(A12="","",IFERROR(INDEX('Identificación y Versiones'!$B:$B,MATCH(A12,'Identificación y Versiones'!$A:$A,0)),"")) | D12: =IF(A12="","",IFERROR(INDEX('Identificación y Versiones'!$F:$F,MATCH(A12,'Identificación y Versiones'!$A:$A,0)),"")) | E12: =IF(A12="","",IFERROR(INDEX('Identificación y Versiones'!$G:$G,MATCH(A12,'Identificación y Versiones'!$A:$A,0)),"")) | F12: =IF(A12="","",IFERROR(INDEX('Identificación y Versiones'!$H:$H,MATCH(A12,'Identificación y Versiones'!$A:$A,0)),"")) | G12: =IF(A12="","",IFERROR(INDEX('Identificación y Versiones'!$I:$I,MATCH(A12,'Identificación y Versiones'!$A:$A,0)),"")) | H12: =IF(A12="","",IFERROR(INDEX('Identificación y Versiones'!$J:$J,MATCH(A12,'Identificación y Versiones'!$A:$A,0)),"")) | I12: =IF(A12="","",IFERROR(INDEX('Identificación y Versiones'!$K:$K,MATCH(A12,'Identificación y Versiones'!$A:$A,0)),"")) | J12: =IF(A12="","",IFERROR(INDEX('Identificación y Versiones'!$N:$N,MATCH(A12,'Identificación y Versiones'!$A:$A,0)),"")) | K12: =IF(A12="","",IFERROR(INDEX('Identificación y Versiones'!$O:$O,MATCH(A12,'Identificación y Versiones'!$A:$A,0)),"")) | L12: =IF(A12="","",IFERROR(INDEX('Identificación y Versiones'!$P:$P,MATCH(A12,'Identificación y Versiones'!$A:$A,0)),"")) | M12: =IF(A12="","",IFERROR(INDEX('Identificación y Versiones'!$Q:$Q,MATCH(A12,'Identificación y Versiones'!$A:$A,0)),"")) | N12: =IF(A12="","",IFERROR(INDEX('Identificación y Versiones'!$R:$R,MATCH(A12,'Identificación y Versiones'!$A:$A,0)),"")) | O12: =IF(A12="","",IFERROR(INDEX('Identificación y Versiones'!$S:$S,MATCH(A12,'Identificación y Versiones'!$A:$A,0)),"")) | P12: =IF(A12="","",IFERROR(INDEX('Identificación y Versiones'!$E:$E,MATCH(A12,'Identificación y Versiones'!$A:$A,0)),"")) | Q12: =IF(A12="","",IFERROR(INDEX('Identificación y Versiones'!$D:$D,MATCH(A12,'Identificación y Versiones'!$A:$A,0)),"")) | R12: =IF(A12="","",IFERROR(INDEX('Identificación y Versiones'!$L:$L,MATCH(A12,'Identificación y Versiones'!$A:$A,0)),"")) | S12: =IF(A12="","",COUNTIF('Casos de Prueba'!$B$2:$B$1000,A12)) | T12: =IF(A12="","",COUNTIFS('Casos de Prueba'!$B$2:$B$1000,A12,'Casos de Prueba'!$J$2:$J$1000,"<>Pendiente",'Casos de Prueba'!$J$2:$J$1000,"<>")) | U12: =IF(A12="","",COUNTIFS('Casos de Prueba'!$B$2:$B$1000,A12,'Casos de Prueba'!$J$2:$J$1000,"Aprobado")) | V12: =IF(A12="","",COUNTIFS('Casos de Prueba'!$B$2:$B$1000,A12,'Casos de Prueba'!$J$2:$J$1000,"Fallido")) | W12: =IF(A12="","",COUNTIFS('Casos de Prueba'!$B$2:$B$1000,A12,'Casos de Prueba'!$J$2:$J$1000,"Bloqueado")) | X12: =IF(A12="","",COUNTIFS('Casos de Prueba'!$B$2:$B$1000,A12,'Casos de Prueba'!$J$2:$J$1000,"Pendiente")) | Y12: =IF(A12="","",COUNTIFS(Incidencias!$C$2:$C$1000,A12,Incidencias!$N$2:$N$1000,"<>Cerrado")-COUNTIFS(Incidencias!$C$2:$C$1000,A12,Incidencias!$N$2:$N$1000,"")) | AD12: =IF(A12="","","Resumen de visita — Sesión "&A12&CHAR(10)&"Fecha de la visita: "&C12&CHAR(10)&"Cliente / Comercio: "&D12&CHAR(10)&"Máquina: "&E12&" "&F12&" (Serial: "&G12&")"&CHAR(10)&"POS: "&H12&" (Serial: "&I12&") — Firmware: "&J12&CHAR(10)&"MDB: "&K12&" / "&L12&" / "&M12&CHAR(10)&"Financiera: "&N12&" | Agente Polaris: "&O12&CHAR(10)&"Participantes: "&P12&" (Responsable: "&Q12&")"&CHAR(10)&"Objetivo: "&R12&CHAR(10)&CHAR(10)&"Resultado de pruebas: "&T12&"/"&S12&" ejecutadas — Aprobadas: "&U12&", Fallidas: "&V12&", Bloqueadas: "&W12&", Pendientes: "&X12&CHAR(10)&"Incidencias abiertas: "&Y12&CHAR(10)&CHAR(10)&"Concepto final: "&AB12&CHAR(10)&"Pendientes: "&AA12)
C13: =IF(A13="","",IFERROR(INDEX('Identificación y Versiones'!$B:$B,MATCH(A13,'Identificación y Versiones'!$A:$A,0)),"")) | D13: =IF(A13="","",IFERROR(INDEX('Identificación y Versiones'!$F:$F,MATCH(A13,'Identificación y Versiones'!$A:$A,0)),"")) | E13: =IF(A13="","",IFERROR(INDEX('Identificación y Versiones'!$G:$G,MATCH(A13,'Identificación y Versiones'!$A:$A,0)),"")) | F13: =IF(A13="","",IFERROR(INDEX('Identificación y Versiones'!$H:$H,MATCH(A13,'Identificación y Versiones'!$A:$A,0)),"")) | G13: =IF(A13="","",IFERROR(INDEX('Identificación y Versiones'!$I:$I,MATCH(A13,'Identificación y Versiones'!$A:$A,0)),"")) | H13: =IF(A13="","",IFERROR(INDEX('Identificación y Versiones'!$J:$J,MATCH(A13,'Identificación y Versiones'!$A:$A,0)),"")) | I13: =IF(A13="","",IFERROR(INDEX('Identificación y Versiones'!$K:$K,MATCH(A13,'Identificación y Versiones'!$A:$A,0)),"")) | J13: =IF(A13="","",IFERROR(INDEX('Identificación y Versiones'!$N:$N,MATCH(A13,'Identificación y Versiones'!$A:$A,0)),"")) | K13: =IF(A13="","",IFERROR(INDEX('Identificación y Versiones'!$O:$O,MATCH(A13,'Identificación y Versiones'!$A:$A,0)),"")) | L13: =IF(A13="","",IFERROR(INDEX('Identificación y Versiones'!$P:$P,MATCH(A13,'Identificación y Versiones'!$A:$A,0)),"")) | M13: =IF(A13="","",IFERROR(INDEX('Identificación y Versiones'!$Q:$Q,MATCH(A13,'Identificación y Versiones'!$A:$A,0)),"")) | N13: =IF(A13="","",IFERROR(INDEX('Identificación y Versiones'!$R:$R,MATCH(A13,'Identificación y Versiones'!$A:$A,0)),"")) | O13: =IF(A13="","",IFERROR(INDEX('Identificación y Versiones'!$S:$S,MATCH(A13,'Identificación y Versiones'!$A:$A,0)),"")) | P13: =IF(A13="","",IFERROR(INDEX('Identificación y Versiones'!$E:$E,MATCH(A13,'Identificación y Versiones'!$A:$A,0)),"")) | Q13: =IF(A13="","",IFERROR(INDEX('Identificación y Versiones'!$D:$D,MATCH(A13,'Identificación y Versiones'!$A:$A,0)),"")) | R13: =IF(A13="","",IFERROR(INDEX('Identificación y Versiones'!$L:$L,MATCH(A13,'Identificación y Versiones'!$A:$A,0)),"")) | S13: =IF(A13="","",COUNTIF('Casos de Prueba'!$B$2:$B$1000,A13)) | T13: =IF(A13="","",COUNTIFS('Casos de Prueba'!$B$2:$B$1000,A13,'Casos de Prueba'!$J$2:$J$1000,"<>Pendiente",'Casos de Prueba'!$J$2:$J$1000,"<>")) | U13: =IF(A13="","",COUNTIFS('Casos de Prueba'!$B$2:$B$1000,A13,'Casos de Prueba'!$J$2:$J$1000,"Aprobado")) | V13: =IF(A13="","",COUNTIFS('Casos de Prueba'!$B$2:$B$1000,A13,'Casos de Prueba'!$J$2:$J$1000,"Fallido")) | W13: =IF(A13="","",COUNTIFS('Casos de Prueba'!$B$2:$B$1000,A13,'Casos de Prueba'!$J$2:$J$1000,"Bloqueado")) | X13: =IF(A13="","",COUNTIFS('Casos de Prueba'!$B$2:$B$1000,A13,'Casos de Prueba'!$J$2:$J$1000,"Pendiente")) | Y13: =IF(A13="","",COUNTIFS(Incidencias!$C$2:$C$1000,A13,Incidencias!$N$2:$N$1000,"<>Cerrado")-COUNTIFS(Incidencias!$C$2:$C$1000,A13,Incidencias!$N$2:$N$1000,"")) | AD13: =IF(A13="","","Resumen de visita — Sesión "&A13&CHAR(10)&"Fecha de la visita: "&C13&CHAR(10)&"Cliente / Comercio: "&D13&CHAR(10)&"Máquina: "&E13&" "&F13&" (Serial: "&G13&")"&CHAR(10)&"POS: "&H13&" (Serial: "&I13&") — Firmware: "&J13&CHAR(10)&"MDB: "&K13&" / "&L13&" / "&M13&CHAR(10)&"Financiera: "&N13&" | Agente Polaris: "&O13&CHAR(10)&"Participantes: "&P13&" (Responsable: "&Q13&")"&CHAR(10)&"Objetivo: "&R13&CHAR(10)&CHAR(10)&"Resultado de pruebas: "&T13&"/"&S13&" ejecutadas — Aprobadas: "&U13&", Fallidas: "&V13&", Bloqueadas: "&W13&", Pendientes: "&X13&CHAR(10)&"Incidencias abiertas: "&Y13&CHAR(10)&CHAR(10)&"Concepto final: "&AB13&CHAR(10)&"Pendientes: "&AA13)
